<h2>Promise.resolve(value) и Promise.reject(error)</h2>

<div class="v-method-wrapper">
    <v-method before="" method="Promise.resolve" after="" arg="(value)">создаёт успешно выполнившийся промис с результатом value. Используют, когда хотят построить асинхронную цепочку, и начальный результат уже есть</v-method>
	<v-method-arg arg="value">результат</v-method-arg>
</div>

<div class="v-method-wrapper">
    <v-method before="" method="Promise.reject" after="" arg="(error)">создаёт уже выполнившийся промис с ошибкой error. Используется очень редко, т.к. ошибка возникает обычно не в начале цепочки, а в процессе её выполнения</v-method>
	<v-method-arg arg="error">ошибка</v-method-arg>
</div>

<v-two-code type="js;js" comment=";">
<template v-slot:first>
Promise.resolve(55)
	.then(val => console.log(val))
</template>
<template v-slot:last>
Promise.reject(new Error("..."))
	.catch(val => console.log(val))
</template>
</v-two-code>
